{\rtf1\ansi\ansicpg1252\cocoartf2512
\cocoatextscaling0\cocoaplatform0{\fonttbl\f0\fmodern\fcharset0 Courier;\f1\fmodern\fcharset0 Courier-Bold;}
{\colortbl;\red255\green255\blue255;\red255\green255\blue255;\red23\green119\blue54;\red91\green225\blue239;
\red253\green161\blue46;\red93\green235\blue68;}
{\*\expandedcolortbl;;\csgray\c100000;\cspthree\c24442\c52131\c29897;\cssrgb\c41043\c89975\c95013;
\cssrgb\c100000\c69020\c23137;\cssrgb\c41739\c91950\c33578;}
\margl1440\margr1440\vieww10800\viewh8400\viewkind0
\pard\tx560\tx1120\tx1680\tx2240\tx2800\tx3360\tx3920\tx4480\tx5040\tx5600\tx6160\tx6720\pardirnatural\partightenfactor0

\f0\fs24 \cf2 \cb3 \CocoaLigature0 >>> from dojo_ninjas_app.models import*\
>>> dojos.objects.create(name="OC",city="Costa Mesa",state="CA")\
<dojos: dojos object (1)>\
>>> dojos.objects.create(name="Seattle",city="Seattle",state="WA")\
<dojos: dojos object (2)>\
>>> dojos.objects.create(name="Boise",city="Boise",state="ID")\
<dojos: dojos object (3)>\
>>> dojos.objects.all().delete()\
(3, \{'dojo_ninjas_app.ninjas': 0, 'dojo_ninjas_app.dojos': 3\})\
>>> dojos.objects.all()\
<QuerySet []>\
>>> dojos.objects.create(name="OC",city="Costa Mesa",state="CA")\
<dojos: dojos object (4)>\
>>> dojos.objects.create(name="Seattle",city="Seattle",state="WA")\
<dojos: dojos object (5)>\
>>> dojos.objects.create(name="Boise",city="Boise",state="ID")\
<dojos: dojos object (6)>\
>>> ninjas.objects.create(first_name="Johnny",last_name="Walker",dojo-"OC")\
  File "<console>", line 1\
SyntaxError: positional argument follows keyword argument\
>>> ninjas.objects.create(first_name="Johnny",last_name="Walker",dojo="OC")\
Traceback (most recent call last):\
  File "<console>", line 1, in <module>\
  File "/Users/ben/Desktop/Dojo_assignments/Python/my_environments/djangoPy3Env/lib/python3.8/site-packages/django/db/models/manager.py", line 82, in manager_method\
    return getattr(self.get_queryset(), name)(*args, **kwargs)\
  File "/Users/ben/Desktop/Dojo_assignments/Python/my_environments/djangoPy3Env/lib/python3.8/site-packages/django/db/models/query.py", line 420, in create\
    obj = self.model(**kwargs)\
  File "/Users/ben/Desktop/Dojo_assignments/Python/my_environments/djangoPy3Env/lib/python3.8/site-packages/django/db/models/base.py", line 483, in __init__\
    _setattr(self, field.name, rel_obj)\
  File "/Users/ben/Desktop/Dojo_assignments/Python/my_environments/djangoPy3Env/lib/python3.8/site-packages/django/db/models/fields/related_descriptors.py", line 206, in __set__\
    raise ValueError(\
ValueError: Cannot assign "'OC'": "ninjas.dojo" must be a "dojos" instance.\
>>> ninjas.objects.create(first_name="Johnny",last_name="Walker",dojo_id=1)\
Traceback (most recent call last):\
  File "/Users/ben/Desktop/Dojo_assignments/Python/my_environments/djangoPy3Env/lib/python3.8/site-packages/django/db/backends/utils.py", line 84, in _execute\
    return self.cursor.execute(sql, params)\
  File "/Users/ben/Desktop/Dojo_assignments/Python/my_environments/djangoPy3Env/lib/python3.8/site-packages/django/db/backends/sqlite3/base.py", line 383, in execute\
    return Database.Cursor.execute(self, query, params)\
sqlite3.IntegrityError: FOREIGN KEY constraint failed\
\
The above exception was the direct cause of the following exception:\
\
Traceback (most recent call last):\
  File "<console>", line 1, in <module>\
  File "/Users/ben/Desktop/Dojo_assignments/Python/my_environments/djangoPy3Env/lib/python3.8/site-packages/django/db/models/manager.py", line 82, in manager_method\
    return getattr(self.get_queryset(), name)(*args, **kwargs)\
  File "/Users/ben/Desktop/Dojo_assignments/Python/my_environments/djangoPy3Env/lib/python3.8/site-packages/django/db/models/query.py", line 422, in create\
    obj.save(force_insert=True, using=self.db)\
  File "/Users/ben/Desktop/Dojo_assignments/Python/my_environments/djangoPy3Env/lib/python3.8/site-packages/django/db/models/base.py", line 740, in save\
    self.save_base(using=using, force_insert=force_insert,\
  File "/Users/ben/Desktop/Dojo_assignments/Python/my_environments/djangoPy3Env/lib/python3.8/site-packages/django/db/models/base.py", line 777, in save_base\
    updated = self._save_table(\
  File "/Users/ben/Desktop/Dojo_assignments/Python/my_environments/djangoPy3Env/lib/python3.8/site-packages/django/db/models/base.py", line 870, in _save_table\
    result = self._do_insert(cls._base_manager, using, fields, update_pk, raw)\
  File "/Users/ben/Desktop/Dojo_assignments/Python/my_environments/djangoPy3Env/lib/python3.8/site-packages/django/db/models/base.py", line 907, in _do_insert\
    return manager._insert([self], fields=fields, return_id=update_pk,\
  File "/Users/ben/Desktop/Dojo_assignments/Python/my_environments/djangoPy3Env/lib/python3.8/site-packages/django/db/models/manager.py", line 82, in manager_method\
    return getattr(self.get_queryset(), name)(*args, **kwargs)\
  File "/Users/ben/Desktop/Dojo_assignments/Python/my_environments/djangoPy3Env/lib/python3.8/site-packages/django/db/models/query.py", line 1186, in _insert\
    return query.get_compiler(using=using).execute_sql(return_id)\
  File "/Users/ben/Desktop/Dojo_assignments/Python/my_environments/djangoPy3Env/lib/python3.8/site-packages/django/db/models/sql/compiler.py", line 1335, in execute_sql\
    cursor.execute(sql, params)\
  File "/Users/ben/Desktop/Dojo_assignments/Python/my_environments/djangoPy3Env/lib/python3.8/site-packages/django/db/backends/utils.py", line 99, in execute\
    return super().execute(sql, params)\
  File "/Users/ben/Desktop/Dojo_assignments/Python/my_environments/djangoPy3Env/lib/python3.8/site-packages/django/db/backends/utils.py", line 67, in execute\
    return self._execute_with_wrappers(sql, params, many=False, executor=self._execute)\
  File "/Users/ben/Desktop/Dojo_assignments/Python/my_environments/djangoPy3Env/lib/python3.8/site-packages/django/db/backends/utils.py", line 76, in _execute_with_wrappers\
    return executor(sql, params, many, context)\
  File "/Users/ben/Desktop/Dojo_assignments/Python/my_environments/djangoPy3Env/lib/python3.8/site-packages/django/db/backends/utils.py", line 84, in _execute\
    return self.cursor.execute(sql, params)\
  File "/Users/ben/Desktop/Dojo_assignments/Python/my_environments/djangoPy3Env/lib/python3.8/site-packages/django/db/utils.py", line 89, in __exit__\
    raise dj_exc_value.with_traceback(traceback) from exc_value\
  File "/Users/ben/Desktop/Dojo_assignments/Python/my_environments/djangoPy3Env/lib/python3.8/site-packages/django/db/backends/utils.py", line 84, in _execute\
    return self.cursor.execute(sql, params)\
  File "/Users/ben/Desktop/Dojo_assignments/Python/my_environments/djangoPy3Env/lib/python3.8/site-packages/django/db/backends/sqlite3/base.py", line 383, in execute\
    return Database.Cursor.execute(self, query, params)\
django.db.utils.IntegrityError: FOREIGN KEY constraint failed\
>>> ninjas.objects.create(first_name="Johnny",last_name="Walker",dojo_id=1)\
Traceback (most recent call last):\
  File "/Users/ben/Desktop/Dojo_assignments/Python/my_environments/djangoPy3Env/lib/python3.8/site-packages/django/db/backends/utils.py", line 84, in _execute\
    return self.cursor.execute(sql, params)\
  File "/Users/ben/Desktop/Dojo_assignments/Python/my_environments/djangoPy3Env/lib/python3.8/site-packages/django/db/backends/sqlite3/base.py", line 383, in execute\
    return Database.Cursor.execute(self, query, params)\
sqlite3.IntegrityError: FOREIGN KEY constraint failed\
\
The above exception was the direct cause of the following exception:\
\
Traceback (most recent call last):\
  File "<console>", line 1, in <module>\
  File "/Users/ben/Desktop/Dojo_assignments/Python/my_environments/djangoPy3Env/lib/python3.8/site-packages/django/db/models/manager.py", line 82, in manager_method\
    return getattr(self.get_queryset(), name)(*args, **kwargs)\
  File "/Users/ben/Desktop/Dojo_assignments/Python/my_environments/djangoPy3Env/lib/python3.8/site-packages/django/db/models/query.py", line 422, in create\
    obj.save(force_insert=True, using=self.db)\
  File "/Users/ben/Desktop/Dojo_assignments/Python/my_environments/djangoPy3Env/lib/python3.8/site-packages/django/db/models/base.py", line 740, in save\
    self.save_base(using=using, force_insert=force_insert,\
  File "/Users/ben/Desktop/Dojo_assignments/Python/my_environments/djangoPy3Env/lib/python3.8/site-packages/django/db/models/base.py", line 777, in save_base\
    updated = self._save_table(\
  File "/Users/ben/Desktop/Dojo_assignments/Python/my_environments/djangoPy3Env/lib/python3.8/site-packages/django/db/models/base.py", line 870, in _save_table\
    result = self._do_insert(cls._base_manager, using, fields, update_pk, raw)\
  File "/Users/ben/Desktop/Dojo_assignments/Python/my_environments/djangoPy3Env/lib/python3.8/site-packages/django/db/models/base.py", line 907, in _do_insert\
    return manager._insert([self], fields=fields, return_id=update_pk,\
  File "/Users/ben/Desktop/Dojo_assignments/Python/my_environments/djangoPy3Env/lib/python3.8/site-packages/django/db/models/manager.py", line 82, in manager_method\
    return getattr(self.get_queryset(), name)(*args, **kwargs)\
  File "/Users/ben/Desktop/Dojo_assignments/Python/my_environments/djangoPy3Env/lib/python3.8/site-packages/django/db/models/query.py", line 1186, in _insert\
    return query.get_compiler(using=using).execute_sql(return_id)\
  File "/Users/ben/Desktop/Dojo_assignments/Python/my_environments/djangoPy3Env/lib/python3.8/site-packages/django/db/models/sql/compiler.py", line 1335, in execute_sql\
    cursor.execute(sql, params)\
  File "/Users/ben/Desktop/Dojo_assignments/Python/my_environments/djangoPy3Env/lib/python3.8/site-packages/django/db/backends/utils.py", line 99, in execute\
    return super().execute(sql, params)\
  File "/Users/ben/Desktop/Dojo_assignments/Python/my_environments/djangoPy3Env/lib/python3.8/site-packages/django/db/backends/utils.py", line 67, in execute\
    return self._execute_with_wrappers(sql, params, many=False, executor=self._execute)\
  File "/Users/ben/Desktop/Dojo_assignments/Python/my_environments/djangoPy3Env/lib/python3.8/site-packages/django/db/backends/utils.py", line 76, in _execute_with_wrappers\
    return executor(sql, params, many, context)\
  File "/Users/ben/Desktop/Dojo_assignments/Python/my_environments/djangoPy3Env/lib/python3.8/site-packages/django/db/backends/utils.py", line 84, in _execute\
    return self.cursor.execute(sql, params)\
  File "/Users/ben/Desktop/Dojo_assignments/Python/my_environments/djangoPy3Env/lib/python3.8/site-packages/django/db/utils.py", line 89, in __exit__\
    raise dj_exc_value.with_traceback(traceback) from exc_value\
  File "/Users/ben/Desktop/Dojo_assignments/Python/my_environments/djangoPy3Env/lib/python3.8/site-packages/django/db/backends/utils.py", line 84, in _execute\
    return self.cursor.execute(sql, params)\
  File "/Users/ben/Desktop/Dojo_assignments/Python/my_environments/djangoPy3Env/lib/python3.8/site-packages/django/db/backends/sqlite3/base.py", line 383, in execute\
    return Database.Cursor.execute(self, query, params)\
django.db.utils.IntegrityError: FOREIGN KEY constraint failed\
>>> ninjas.objects.create(first_name="Johnny",last_name="Walker",dojo_id_id=1)\
Traceback (most recent call last):\
  File "<console>", line 1, in <module>\
  File "/Users/ben/Desktop/Dojo_assignments/Python/my_environments/djangoPy3Env/lib/python3.8/site-packages/django/db/models/manager.py", line 82, in manager_method\
    return getattr(self.get_queryset(), name)(*args, **kwargs)\
  File "/Users/ben/Desktop/Dojo_assignments/Python/my_environments/djangoPy3Env/lib/python3.8/site-packages/django/db/models/query.py", line 420, in create\
    obj = self.model(**kwargs)\
  File "/Users/ben/Desktop/Dojo_assignments/Python/my_environments/djangoPy3Env/lib/python3.8/site-packages/django/db/models/base.py", line 501, in __init__\
    raise TypeError("%s() got an unexpected keyword argument '%s'" % (cls.__name__, kwarg))\
TypeError: ninjas() got an unexpected keyword argument 'dojo_id_id'\
>>> exit()\
(djangoPy3Env) ben@Bens-MBP dojo_ninjas_proj % python manage.py makemigrations\

\f1\b \cf4 Migrations for 'dojo_ninjas_app':
\f0\b0 \cf2 \
  
\f1\b \cf5 dojo_ninjas_app/migrations/0002_auto_20200512_1913.py
\f0\b0 \cf2 \
    - Alter field dojo on ninjas\
(djangoPy3Env) ben@Bens-MBP dojo_ninjas_proj % python manage.py migrate\

\f1\b \cf4 Operations to perform:
\f0\b0 \cf2 \

\f1\b \cf5   Apply all migrations: 
\f0\b0 \cf2 admin, auth, contenttypes, dojo_ninjas_app, sessions\

\f1\b \cf4 Running migrations:
\f0\b0 \cf2 \
  Applying dojo_ninjas_app.0002_auto_20200512_1913...
\f1\b \cf6  OK
\f0\b0 \cf2 \
(djangoPy3Env) ben@Bens-MBP dojo_ninjas_proj % python manage.py shell\
Python 3.8.2 (v3.8.2:7b3ab5921f, Feb 24 2020, 17:52:18) \
[Clang 6.0 (clang-600.0.57)] on darwin\
Type "help", "copyright", "credits" or "license" for more information.\
(InteractiveConsole)\
>>> from dojo_ninja_app.models import *\
Traceback (most recent call last):\
  File "<console>", line 1, in <module>\
ModuleNotFoundError: No module named 'dojo_ninja_app'\
>>> from dojo_ninjas_app.models import *\
>>> dojos.objects.all()\
<QuerySet [<dojos: dojos object (4)>, <dojos: dojos object (5)>, <dojos: dojos object (6)>]>\
>>> ninjas.objects.create(first_name="Johhny",last_name="Walker",ninjas_id=4)\
Traceback (most recent call last):\
  File "<console>", line 1, in <module>\
  File "/Users/ben/Desktop/Dojo_assignments/Python/my_environments/djangoPy3Env/lib/python3.8/site-packages/django/db/models/manager.py", line 82, in manager_method\
    return getattr(self.get_queryset(), name)(*args, **kwargs)\
  File "/Users/ben/Desktop/Dojo_assignments/Python/my_environments/djangoPy3Env/lib/python3.8/site-packages/django/db/models/query.py", line 420, in create\
    obj = self.model(**kwargs)\
  File "/Users/ben/Desktop/Dojo_assignments/Python/my_environments/djangoPy3Env/lib/python3.8/site-packages/django/db/models/base.py", line 501, in __init__\
    raise TypeError("%s() got an unexpected keyword argument '%s'" % (cls.__name__, kwarg))\
TypeError: ninjas() got an unexpected keyword argument 'ninjas_id'\
>>> ninjas.objects.create(first_name="Johhny",last_name="Walker",ninjas_id=5)\
Traceback (most recent call last):\
  File "<console>", line 1, in <module>\
  File "/Users/ben/Desktop/Dojo_assignments/Python/my_environments/djangoPy3Env/lib/python3.8/site-packages/django/db/models/manager.py", line 82, in manager_method\
    return getattr(self.get_queryset(), name)(*args, **kwargs)\
  File "/Users/ben/Desktop/Dojo_assignments/Python/my_environments/djangoPy3Env/lib/python3.8/site-packages/django/db/models/query.py", line 420, in create\
    obj = self.model(**kwargs)\
  File "/Users/ben/Desktop/Dojo_assignments/Python/my_environments/djangoPy3Env/lib/python3.8/site-packages/django/db/models/base.py", line 501, in __init__\
    raise TypeError("%s() got an unexpected keyword argument '%s'" % (cls.__name__, kwarg))\
TypeError: ninjas() got an unexpected keyword argument 'ninjas_id'\
>>> ninjas.objects.create(first_name="Johhny",last_name="Walker",dojo_id=5)\
<ninjas: ninjas object (1)>\
>>> ninjas.objects.create(first_name="Timmy",last_name="Thomas",dojo_id=5)\
<ninjas: ninjas object (2)>\
>>> ninjas.objects.create(first_name="Jimmy",last_name="Thomas",dojo_id=5)\
<ninjas: ninjas object (3)>\
>>> ninjas.objects.create(first_name="Jimmy",last_name="Brooks",dojo_id=6)\
<ninjas: ninjas object (4)>\
>>> ninjas.objects.create(first_name="Timmy",last_name="Brooks",dojo_id=6)\
<ninjas: ninjas object (5)>\
>>> ninjas.objects.create(first_name="Kimmy",last_name="Brooks",dojo_id=6)\
<ninjas: ninjas object (6)>\
>>> ninjas.objects.create(first_name="Kimmy",last_name="Johnson",dojo_id=7)\
Traceback (most recent call last):\
  File "/Users/ben/Desktop/Dojo_assignments/Python/my_environments/djangoPy3Env/lib/python3.8/site-packages/django/db/backends/utils.py", line 84, in _execute\
    return self.cursor.execute(sql, params)\
  File "/Users/ben/Desktop/Dojo_assignments/Python/my_environments/djangoPy3Env/lib/python3.8/site-packages/django/db/backends/sqlite3/base.py", line 383, in execute\
    return Database.Cursor.execute(self, query, params)\
sqlite3.IntegrityError: FOREIGN KEY constraint failed\
\
The above exception was the direct cause of the following exception:\
\
Traceback (most recent call last):\
  File "<console>", line 1, in <module>\
  File "/Users/ben/Desktop/Dojo_assignments/Python/my_environments/djangoPy3Env/lib/python3.8/site-packages/django/db/models/manager.py", line 82, in manager_method\
    return getattr(self.get_queryset(), name)(*args, **kwargs)\
  File "/Users/ben/Desktop/Dojo_assignments/Python/my_environments/djangoPy3Env/lib/python3.8/site-packages/django/db/models/query.py", line 422, in create\
    obj.save(force_insert=True, using=self.db)\
  File "/Users/ben/Desktop/Dojo_assignments/Python/my_environments/djangoPy3Env/lib/python3.8/site-packages/django/db/models/base.py", line 740, in save\
    self.save_base(using=using, force_insert=force_insert,\
  File "/Users/ben/Desktop/Dojo_assignments/Python/my_environments/djangoPy3Env/lib/python3.8/site-packages/django/db/models/base.py", line 777, in save_base\
    updated = self._save_table(\
  File "/Users/ben/Desktop/Dojo_assignments/Python/my_environments/djangoPy3Env/lib/python3.8/site-packages/django/db/models/base.py", line 870, in _save_table\
    result = self._do_insert(cls._base_manager, using, fields, update_pk, raw)\
  File "/Users/ben/Desktop/Dojo_assignments/Python/my_environments/djangoPy3Env/lib/python3.8/site-packages/django/db/models/base.py", line 907, in _do_insert\
    return manager._insert([self], fields=fields, return_id=update_pk,\
  File "/Users/ben/Desktop/Dojo_assignments/Python/my_environments/djangoPy3Env/lib/python3.8/site-packages/django/db/models/manager.py", line 82, in manager_method\
    return getattr(self.get_queryset(), name)(*args, **kwargs)\
  File "/Users/ben/Desktop/Dojo_assignments/Python/my_environments/djangoPy3Env/lib/python3.8/site-packages/django/db/models/query.py", line 1186, in _insert\
    return query.get_compiler(using=using).execute_sql(return_id)\
  File "/Users/ben/Desktop/Dojo_assignments/Python/my_environments/djangoPy3Env/lib/python3.8/site-packages/django/db/models/sql/compiler.py", line 1335, in execute_sql\
    cursor.execute(sql, params)\
  File "/Users/ben/Desktop/Dojo_assignments/Python/my_environments/djangoPy3Env/lib/python3.8/site-packages/django/db/backends/utils.py", line 99, in execute\
    return super().execute(sql, params)\
  File "/Users/ben/Desktop/Dojo_assignments/Python/my_environments/djangoPy3Env/lib/python3.8/site-packages/django/db/backends/utils.py", line 67, in execute\
    return self._execute_with_wrappers(sql, params, many=False, executor=self._execute)\
  File "/Users/ben/Desktop/Dojo_assignments/Python/my_environments/djangoPy3Env/lib/python3.8/site-packages/django/db/backends/utils.py", line 76, in _execute_with_wrappers\
    return executor(sql, params, many, context)\
  File "/Users/ben/Desktop/Dojo_assignments/Python/my_environments/djangoPy3Env/lib/python3.8/site-packages/django/db/backends/utils.py", line 84, in _execute\
    return self.cursor.execute(sql, params)\
  File "/Users/ben/Desktop/Dojo_assignments/Python/my_environments/djangoPy3Env/lib/python3.8/site-packages/django/db/utils.py", line 89, in __exit__\
    raise dj_exc_value.with_traceback(traceback) from exc_value\
  File "/Users/ben/Desktop/Dojo_assignments/Python/my_environments/djangoPy3Env/lib/python3.8/site-packages/django/db/backends/utils.py", line 84, in _execute\
    return self.cursor.execute(sql, params)\
  File "/Users/ben/Desktop/Dojo_assignments/Python/my_environments/djangoPy3Env/lib/python3.8/site-packages/django/db/backends/sqlite3/base.py", line 383, in execute\
    return Database.Cursor.execute(self, query, params)\
django.db.utils.IntegrityError: FOREIGN KEY constraint failed\
>>> ninjas.objects.create(first_name="Kimmy",last_name="Johnson",dojo_id=4)\
<ninjas: ninjas object (7)>\
>>> ninjas.objects.create(first_name="Jimmy",last_name="Johnson",dojo_id=4)\
<ninjas: ninjas object (8)>\
>>> ninjas.objects.create(first_name="Timmy",last_name="Johnson",dojo_id=4)\
<ninjas: ninjas object (9)>\
>>> ninjas.objects.get(dojo_id=4)\
Traceback (most recent call last):\
  File "<console>", line 1, in <module>\
  File "/Users/ben/Desktop/Dojo_assignments/Python/my_environments/djangoPy3Env/lib/python3.8/site-packages/django/db/models/manager.py", line 82, in manager_method\
    return getattr(self.get_queryset(), name)(*args, **kwargs)\
  File "/Users/ben/Desktop/Dojo_assignments/Python/my_environments/djangoPy3Env/lib/python3.8/site-packages/django/db/models/query.py", line 410, in get\
    raise self.model.MultipleObjectsReturned(\
dojo_ninjas_app.models.ninjas.MultipleObjectsReturned: get() returned more than one ninjas -- it returned 3!\
>>> ninjas.objects.filter(dojo_id=4)\
<QuerySet [<ninjas: ninjas object (7)>, <ninjas: ninjas object (8)>, <ninjas: ninjas object (9)>]>\
>>> ninjas.objects.filter(dojo_id=5)\
<QuerySet [<ninjas: ninjas object (1)>, <ninjas: ninjas object (2)>, <ninjas: ninjas object (3)>]>\
>>> ninjas.objects.filter(dojo_id=6)\
<QuerySet [<ninjas: ninjas object (4)>, <ninjas: ninjas object (5)>, <ninjas: ninjas object (6)>]>\
>>> exit()\
(djangoPy3Env) ben@Bens-MBP dojo_ninjas_proj % python manage.py makemigrations\
You are trying to add a non-nullable field 'desc' to dojos without a default; we can't do that (the database needs something to populate existing rows).\
Please select a fix:\
 1) Provide a one-off default now (will be set on all existing rows with a null value for this column)\
 2) Quit, and let me add a default in models.py\
Select an option: 1\
Please enter the default value now, as valid Python\
The datetime and django.utils.timezone modules are available, so you can do e.g. timezone.now\
Type 'exit' to exit this prompt\
>>> "old dojo"\

\f1\b \cf4 Migrations for 'dojo_ninjas_app':
\f0\b0 \cf2 \
  
\f1\b \cf5 dojo_ninjas_app/migrations/0003_dojos_desc.py
\f0\b0 \cf2 \
    - Add field desc to dojos\
(djangoPy3Env) ben@Bens-MBP dojo_ninjas_proj % python manage.py migrate\

\f1\b \cf4 Operations to perform:
\f0\b0 \cf2 \

\f1\b \cf5   Apply all migrations: 
\f0\b0 \cf2 admin, auth, contenttypes, dojo_ninjas_app, sessions\

\f1\b \cf4 Running migrations:
\f0\b0 \cf2 \
  Applying dojo_ninjas_app.0003_dojos_desc...
\f1\b \cf6  OK
\f0\b0 \cf2 \
(djangoPy3Env) ben@Bens-MBP dojo_ninjas_proj % python manage.py shell\
Python 3.8.2 (v3.8.2:7b3ab5921f, Feb 24 2020, 17:52:18) \
[Clang 6.0 (clang-600.0.57)] on darwin\
Type "help", "copyright", "credits" or "license" for more information.\
(InteractiveConsole)\
>>> from dojo_ninja_app.models import *\
Traceback (most recent call last):\
  File "<console>", line 1, in <module>\
ModuleNotFoundError: No module named 'dojo_ninja_app'\
>>> from dojo_ninjas_app.models import *\
>>> dojos.objects.create(name="BC",city="Vancouver",state="BC",desc="Beautiful British Columbia")\
<dojos: dojos object (7)>\
>>> \
}